Traceback (most recent call last):
  File "C:\Users\khthe\AppData\Local\Programs\Python\envs\py311\Lib\site-packages\jupyter_cache\executors\utils.py", line 58, in single_nb_execution
    executenb(
  File "C:\Users\khthe\AppData\Local\Programs\Python\envs\py311\Lib\site-packages\nbclient\client.py", line 1265, in execute
    return NotebookClient(nb=nb, resources=resources, km=km, **kwargs).execute()
           ^^^^^^^^^^^^^^^^^^^^^^^^^^^^^^^^^^^^^^^^^^^^^^^^^^^^^^^^^^^^^^^^^^^^^
  File "C:\Users\khthe\AppData\Local\Programs\Python\envs\py311\Lib\site-packages\jupyter_core\utils\__init__.py", line 166, in wrapped
    return loop.run_until_complete(inner)
           ^^^^^^^^^^^^^^^^^^^^^^^^^^^^^^
  File "C:\Users\khthe\AppData\Local\Programs\Python\Python311\Lib\asyncio\base_events.py", line 653, in run_until_complete
    return future.result()
           ^^^^^^^^^^^^^^^
  File "C:\Users\khthe\AppData\Local\Programs\Python\envs\py311\Lib\site-packages\nbclient\client.py", line 703, in async_execute
    await self.async_execute_cell(
  File "C:\Users\khthe\AppData\Local\Programs\Python\envs\py311\Lib\site-packages\nbclient\client.py", line 1021, in async_execute_cell
    await self._check_raise_for_error(cell, cell_index, exec_reply)
  File "C:\Users\khthe\AppData\Local\Programs\Python\envs\py311\Lib\site-packages\nbclient\client.py", line 915, in _check_raise_for_error
    raise CellExecutionError.from_cell_and_msg(cell, exec_reply_content)
nbclient.exceptions.CellExecutionError: An error occurred while executing the following cell:
------------------
noten['Maike']
------------------

[1;31m---------------------------------------------------------------------------[0m
[1;31mKeyError[0m                                  Traceback (most recent call last)
Cell [1;32mIn[7], line 1[0m
[1;32m----> 1[0m [43mnoten[49m[43m[[49m[38;5;124;43m'[39;49m[38;5;124;43mMaike[39;49m[38;5;124;43m'[39;49m[43m][49m

[1;31mKeyError[0m: 'Maike'
KeyError: 'Maike'

